Workbook

Sheet Inventory
A1: SKU/ID | B1: Item Nameitm | C1: Daily Rate | D1: Total Quantity Owned
A2: CAM-001 | B2: Sony a7iv Camera Body 84 | C2: 6000 | D2: 1
A3: CAM-002 | B3: Sony a7iv Camera Body 72 | C3: 6000 | D3: 1
A4: LNS-001 | B4: Sigma 70-200mm f/2.8 DG DN OS Sports Lens (Sony E) | C4: 5000 | D4: 1
A5: LNS-002 | B5: Sony FE 24-70mm f/2.8 GM II Lens | C5: 5000 | D5: 1
A6: LNS-003 | B6: Sony FE 50mm f/1.4 GM Lens | C6: 4000 | D6: 1
A7: LNS-004 | B7: Sigma 85 mm f/1.4 DG DN Art Lens for Sony E | C7: 3500 | D7: 1
A8: LNS-005 | B8: Sigma 20 mm f/1.4 DG DN Art Lens for Sony E | C8: 3500 | D8: 1
A9: LNS-006 | B9: Sigma 35 mm f/1.4 DG DN Art Lens for Sony E | C9: 3500 | D9: 1
A10: LNS-007 | B10: Sony FE 50mm f/1.8 Lens | C10: 2000 | D10: 1
A11: DRN-001 | B11: DJI Air 3S Drone with RC 2 Fly More Combo | C11: 18000 | D11: 1
A12: LGT-001 | B12: Godox AD600Pro Witstro All in one Outdoor Flash With Godox P90 Parabolic Softbox with Stand | C12: 6000 | D12: 1
A13: LGT-002 | B13: Godox AD600BM II Witstro Manual All-In-One Outdoor Flash with Godox P90 Parabolic Softbox and Stand | C13: 5500 | D13: 1
... A46: CAM-003 | B46: GoPro HERO 8 Black | C46: 2500 | D46: 1
A47: BAG-001 | B47: Side Bag | C47: Free | D47: 2
A48: BAG-002 | B48: Lense Bag | C48: Free | D48: 4
A49: STB-003 | B49: Mobile gimble 7P | C49: 2500 | D49: 1
A50: PWR-003f | B50: Free-Sony NP FZ100 Rechargeable Lithium Ion Battery | C50: Free | D50: 3
A51: PWR-004f | B51: Free_AXG K&F NP-FZ100 Battery for Sony | C51: Free | D51: 1
A52: PWR-005f | B52: Free-Nitecore NP-FZ100 Battery for Sony | C52: Free | D52: 1
A53: MEM-002f | B53: Free-SanDisk 64GB Extreme PRO UHS I SDXC 200MBps Memory Card | C53: Free | D53: 6
A54: PWR-009f | B54: Free-camera charger cable | C54: Free | D54: 1
A55: PWR-008f | B55: Free-Sony Battery Charger | C55: Free | D55: 1
A56: BAG-003 | B56: K&F Camera Backpack | C56: 1000 | D56: 1

Sheet Bookings
A1: Booking ID | B1: Customer ID | C1: Customer Name | D1: Item | E1: Start Date | F1: End Date | G1: Unit Price | H1: Status | I1: Total Price
A2: 275 | B2: 14 | C2: =VLOOKUP(B2,Customer!A:B,2,FALSE) -> Hirusha Lakshika Rupasingha | D2: Sigma 35 mm f/1.4 DG DN Art Lens for Sony E | E2: 46051 | F2: 46052 | G2: =IFERROR(VLOOKUP(D2,Inventory!B:C,2,FALSE),"") -> 3500 | H2: Booked | I2: 11000
C3: =VLOOKUP(B3,Customer!A:B,2,FALSE) -> #N/A | D3: Godox V1 Flash for Sony | E3: 46051 | F3: 46052 | G3: =IFERROR(VLOOKUP(D3,Inventory!B:C,2,FALSE),"") -> 2000
C4: =VLOOKUP(B4,Customer!A:B,2,FALSE) -> #N/A | D4: Side Bag | G4: =IFERROR(VLOOKUP(D4,Inventory!B:C,2,FALSE),"") -> Free
A5: 310 | B5: 64 | C5: =VLOOKUP(B5,Customer!A:B,2,FALSE) -> Kuda Mannalage Keerthi Ranjith | D5: Sigma 85 mm f/1.4 DG DN Art Lens for Sony E | E5: 46051 | F5: 46051 | G5: =IFERROR(VLOOKUP(D5,Inventory!B:C,2,FALSE),"") -> 3500
C6: =VLOOKUP(B6,Customer!A:B,2,FALSE) -> #N/A | D6: Lense Bag | G6: =IFERROR(VLOOKUP(D6,Inventory!B:C,2,FALSE),"") -> Free
A7: 312 | B7: 39 | C7: =VLOOKUP(B7,Customer!A:B,2,FALSE) -> Hewa Magallagodage Kamal Sanjeewa | D7: Sigma 85 mm f/1.4 DG DN Art Lens for Sony E | E7: 46050 | F7: 46050 | G7: =IFERROR(VLOOKUP(D7,Inventory!B:C,2,FALSE),"") -> 3500
C8: =VLOOKUP(B8,Customer!A:B,2,FALSE) -> #N/A | D8: Lense Bag | G8: =IFERROR(VLOOKUP(D8,Inventory!B:C,2,FALSE),"") -> Free
A9: 320 | B9: 64 | C9: =VLOOKUP(B9,Customer!A:B,2,FALSE) -> Kuda Mannalage Keerthi Ranjith | D9: Sony FE 50mm f/1.4 GM Lens | E9: 46050 | F9: 46050 | G9: =IFERROR(VLOOKUP(D9,Inventory!B:C,2,FALSE),"") -> 4000
C10: =VLOOKUP(B10,Customer!A:B,2,FALSE) -> #N/A | D10: Lense Bag | G10: =IFERROR(VLOOKUP(D10,Inventory!B:C,2,FALSE),"") -> Free
A11: 330 | B11: 66 | C11: =VLOOKUP(B11,Customer!A:B,2,FALSE) -> Nanayakkara Wewa kandambige Janith Lakshan | D11: Sony FE 24-70mm f/2.8 GM II Lens | E11: 46051 | F11: 46051 | G11: =IFERROR(VLOOKUP(D11,Inventory!B:C,2,FALSE),"") -> 5000
C12: =VLOOKUP(B12,Customer!A:B,2,FALSE) -> #N/A | D12: Lense Bag | G12: =IFERROR(VLOOKUP(D12,Inventory!B:C,2,FALSE),"") -> Free
A13: 336 | B13: 23 | C13: =VLOOKUP(B13,Customer!A:B,2,FALSE) -> Sandul Sithmina Danthanarayana Rosairo | D13: DJI RS 3 Mini Stabilizer | E13: 46055 | F13: 46055 | G13: =IFERROR(VLOOKUP(D13,Inventory!B:C,2,FALSE),"") -> 3500
C14: =VLOOKUP(B14,Customer!A:B,2,FALSE) -> #N/A | G14: =IFERROR(VLOOKUP(D14,Inventory!B:C,2,FALSE),"")
A15: 342 | B15: 9 | C15: =VLOOKUP(B15,Customer!A:B,2,FALSE) -> Buddhika Prasad | D15: Sigma 20 mm f/1.4 DG DN Art Lens for Sony E | E15: 46051 | F15: 46051 | G15: =IFERROR(VLOOKUP(D15,Inventory!B:C,2,FALSE),"") -> 3500
C16: =VLOOKUP(B16,Customer!A:B,2,FALSE) -> #N/A | D16: Lense Bag | G16: =IFERROR(VLOOKUP(D16,Inventory!B:C,2,FALSE),"") -> Free
A17: 344 | B17: 3 | C17: =VLOOKUP(B17,Customer!A:B,2,FALSE) -> Hasitha Weerasinghe | D17: Sony FE 50mm f/1.4 GM Lens | E17: 46058 | F17: 46058 | G17: =IFERROR(VLOOKUP(D17,Inventory!B:C,2,FALSE),"") -> 4000
C18: =VLOOKUP(B18,Customer!A:B,2,FALSE) -> #N/A | D18: Lense Bag | G18: =IFERROR(VLOOKUP(D18,Inventory!B:C,2,FALSE),"") -> Free
A19: 353 | B19: 66 | C19: =VLOOKUP(B19,Customer!A:B,2,FALSE) -> Nanayakkara Wewa kandambige Janith Lakshan | D19: Sony a7iv Camera Body 72 | E19: 46050 | F19: 46050 | G19: =IFERROR(VLOOKUP(D19,Inventory!B:C,2,FALSE),"") -> 6000
C20: =VLOOKUP(B20,Customer!A:B,2,FALSE) -> #N/A | D20: Sony NP FZ100 Rechargeable Lithium Ion Battery | E20: 46050 | F20: 46050 | G20: =IFERROR(VLOOKUP(D20,Inventory!B:C,2,FALSE),"") -> 600
C21: =VLOOKUP(B21,Customer!A:B,2,FALSE) -> #N/A | D21: Nitecore NP-FZ100 Battery for Sony | E21: 46050 | F21: 46050 | G21: =IFERROR(VLOOKUP(D21,Inventory!B:C,2,FALSE),"") -> 500
C22: =VLOOKUP(B22,Customer!A:B,2,FALSE) -> #N/A | D22: Sony Battery Charger | E22: 46050 | F22: 46050 | G22: =IFERROR(VLOOKUP(D22,Inventory!B:C,2,FALSE),"") -> 400
C23: =VLOOKUP(B23,Customer!A:B,2,FALSE) -> #N/A | D23: SanDisk 64GB Extreme PRO UHS I SDXC 200MBps Memory Card | E23: 46050 | F23: 46050 | G23: =IFERROR(VLOOKUP(D23,Inventory!B:C,2,FALSE),"") -> 500
C24: =VLOOKUP(B24,Customer!A:B,2,FALSE) -> #N/A | D24: Sony FE 24-70mm f/2.8 GM II Lens | E24: 46050 | F24: 46050 | G24: =IFERROR(VLOOKUP(D24,Inventory!B:C,2,FALSE),"") -> 5000
C25: =VLOOKUP(B25,Customer!A:B,2,FALSE) -> #N/A | D25: Side Bag | E25: 46050 | F25: 46050 | G25: =IFERROR(VLOOKUP(D25,Inventory!B:C,2,FALSE),"") -> Free
A26: 354 | B26: 66 | C26: =VLOOKUP(B26,Customer!A:B,2,FALSE) -> Nanayakkara Wewa kandambige Janith Lakshan | D26: Sony a7iv Camera Body 72 | E26: 46051 | F26: 46051 | G26: =IFERROR(VLOOKUP(D26,Inventory!B:C,2,FALSE),"") -> 6000
C27: =VLOOKUP(B27,Customer!A:B,2,FALSE) -> #N/A | D27: Sony Battery Charger | E27: 46051 | F27: 46051 | G27: =IFERROR(VLOOKUP(D27,Inventory!B:C,2,FALSE),"") -> 400
C28: =VLOOKUP(B28,Customer!A:B,2,FALSE) -> #N/A | D28: Sony NP FZ100 Rechargeable Lithium Ion Battery | E28: 46051 | F28: 46051 | G28: =IFERROR(VLOOKUP(D28,Inventory!B:C,2,FALSE),"") -> 600
C29: =VLOOKUP(B29,Customer!A:B,2,FALSE) -> #N/A | D29: Nitecore NP-FZ100 Battery for Sony | E29: 46051 | F29: 46051 | G29: =IFERROR(VLOOKUP(D29,Inventory!B:C,2,FALSE),"") -> 500
C30: =VLOOKUP(B30,Customer!A:B,2,FALSE) -> #N/A | D30: SanDisk 64GB Extreme PRO UHS I SDXC 200MBps Memory Card | E30: 46051 | F30: 46051 | G30: =IFERROR(VLOOKUP(D30,Inventory!B:C,2,FALSE),"") -> 500
C31: =VLOOKUP(B31,Customer!A:B,2,FALSE) -> #N/A | D31: Side Bag | E31: 46051 | F31: 46051 | G31: =IFERROR(VLOOKUP(D31,Inventory!B:C,2,FALSE),"") -> Free
A32: 358 | B32: 64 | C32: =VLOOKUP(B32,Customer!A:B,2,FALSE) -> Kuda Mannalage Keerthi Ranjith | D32: Sigma 85 mm f/1.4 DG DN Art Lens for Sony E | E32: 46156 | F32: 46156 | G32: =IFERROR(VLOOKUP(D32,Inventory!B:C,2,FALSE),"") -> 3500
C33: =VLOOKUP(B33,Customer!A:B,2,FALSE) -> #N/A | D33: Lense Bag | E33: 46156 | F33: 46156 | G33: =IFERROR(VLOOKUP(D33,Inventory!B:C,2,FALSE),"") -> Free
A34: 360 | B34: 26 | C34: =VLOOKUP(B34,Customer!A:B,2,FALSE) -> Wikash Rahul De Silwa Weerakkodi | D34: Sony FE 24-70mm f/2.8 GM II Lens | E34: 46053 | F34: 46053 | G34: =IFERROR(VLOOKUP(D34,Inventory!B:C,2,FALSE),"") -> 5000
C35: =VLOOKUP(B35,Customer!A:B,2,FALSE) -> #N/A | D35: Godox V1 Flash for Sony | E35: 46053 | F35: 46053 | G35: =IFERROR(VLOOKUP(D35,Inventory!B:C,2,FALSE),"") -> 2000
C36: =VLOOKUP(B36,Customer!A:B,2,FALSE) -> #N/A | D36: Side Bag | E36: 46053 | F36: 46053 | G36: =IFERROR(VLOOKUP(D36,Inventory!B:C,2,FALSE),"") -> Free
A37: 392 | B37: 64 | C37: =VLOOKUP(B37,Customer!A:B,2,FALSE) -> Kuda Mannalage Keerthi Ranjith | D37: Sigma 85 mm f/1.4 DG DN Art Lens for Sony E | E37: 46148 | F37: 46149 | G37: =IFERROR(VLOOKUP(D37,Inventory!B:C,2,FALSE),"") -> 3500 | I37: 7000
C38: =VLOOKUP(B38,Customer!A:B,2,FALSE) -> #N/A | D38: Lense Bag | E38: 46148 | F38: 46149 | G38: =IFERROR(VLOOKUP(D38,Inventory!B:C,2,FALSE),"") -> Free
A39: 406 | B39: 7 | C39: =VLOOKUP(B39,Customer!A:B,2,FALSE) -> Nadeera Ravindu Lakshan | D39: Sony a7iv Camera Body 72 | E39: 46160 | F39: 46160 | G39: =IFERROR(VLOOKUP(D39,Inventory!B:C,2,FALSE),"") -> 6000 | I39: =SUM(G39:G47) -> 13500
C40: =VLOOKUP(B40,Customer!A:B,2,FALSE) -> #N/A | D40: Sigma 85 mm f/1.4 DG DN Art Lens for Sony E | E40: 46160 | F40: 46160 | G40: =IFERROR(VLOOKUP(D40,Inventory!B:C,2,FALSE),"") -> 3500
...

Sheet Availability
B1: Item to Check | C1: Sony FE 50mm f/1.8 Lens
B2: Desired Start Date | C2: 46150
B3: Desired End Date | C3: 46150
C5: =IF(OR(C1="", C2="", C3=""), "Enter Item & Dates", IF(C3 < C2, "⚠️ End Date is before Start Date", IF(COUNTIFS(Bookings!$D$2:$D$1682, C1, Bookings!$E$2:$E$1682, "<="&C3, Bookings!$F$2:$F$1682, ">="&C2, Bookings!$H$2:$H$1682, "<>Returned") > 0, "❌ ALREADY BOOKED", "✅ AVAILABLE"))) -> ✅ AVAILABLE
B10: Currently Rented Out

Sheet Customer
A1: Customer ID | B1: Full Name | C1: Phone Number | D1: Second Number | E1: NIC / ID Number | F1: Address | G1: ID Photo | H1: Home Contact
A2: 1 | B2: Saranga | C2: 768013158
A3: 2 | B3: Shehara | C3: 773062251 | E3: 200625500819
A4: 3 | B4: Hasitha Weerasinghe | C4: 716498441 | E4: 200308810348
A5: 4 | B5: Dinesh Vidanagamage | C5: 765527705 | E5: 951603457V
A6: 5 | B6: Kasun Rangana | C6: 715954620 | E6: 893544712V
A7: 6 | B7: Gihan Pramudya | C7: 771257034 | E7: 200209905584
A8: 7 | B8: Nadeera Ravindu Lakshan | C8: 779786182 | E8: 980042545V
A9: 8 | B9: Wathukarage Ganindu Devmina | C9: 701882956 | E9: 200414603134
A10: 9 | B10: Buddhika Prasad | C10: 767274680 | E10: 982790875V
A11: 10 | B11: Madduma Walpolage Sahan Viduranga | C11: 719158032 | E11: 200414904170
A12: 11 | B12: Gangabadawaththage Namindu Vishal Sathsara | C12: 724681955 | E12: 200422605000
A13: 12 | B13: Abeweera Arachchige Pasindu Sandakelum | C13: 704972883 | E13: 200211103447
A14: 13 | B14: Abesekara Kaushika Nimsara | C14: 788854286 | E14: 200514700759
A15: 14 | B15: Hirusha Lakshika Rupasingha | C15: 779338639 | D15: 782545233 | E15: 200020601878
A16: 15 | B16: Passaperuma Arachchige Pramod Chathuranga | C16: 719134312 | E16: 951393916V
A17: 16 | B17: Navaraja Prabhashan | C17: 758789173 | D17: 778070220 | E17: 199524000096
A18: 17 | B18: Pullippu Vidana Maheema Yasaswi Weerasekara | C18: 774413827 | E18: 200730700797
A19: 18 | B19: Pramod Yasas Rangana | C19: 767380337 | E19: 200530400336
A20: 19 | B20: Batawalage Don Nethindu Ridmika Shakilan Harischandra | C20: 741887055 | D20: 711468939 | E20: 990751315V
A21: 20 | B21: R.Danoj Sandaruwan | C21: 771305961 | E21: 200134602424
A22: 21 | B22: Ediri Arachchige Sachith Nimantha Madhumadhawa | C22: 763568719 | E22: 200107502790
A23: 22 | B23: Nathage Dhanushka Madushan | C23: 743415806 | D23: 783253188 | E23: 200501502800
A24: 23 | B24: Sandul Sithmina Danthanarayana Rosairo | C24: 740978184 | E24: 200623700470
A25: 24 | B25: Sivaneththige Sehan Lakshitha | C25: 715428809 | E25: 200235801642
A26: 25 | B26: Don Siman Patabendige Senith Ninduwara | C26: 768498534 | E26: 200624400347
A27: 26 | B27: Wikash Rahul De Silwa Weerakkodi | C27: 711191463 | E27: 200532000368
A28: 27 | B28: Ganege Don Chathuranda Randika Abhayasinghe(Retro Shan) | C28: 779361743 | E28: 200332712802
A29: 28 | B29: Punchihewage Dilhan Lakshith | C29: 770157410 | E29: 200004001868
A30: 29 | B30: Nimasha Hansani Abesekara & A.Sachini Kaushalya | C30: 778551338 | E30: 200461401020
A31: 30 | B31: Kalubadanage Ravindu Sachintha Kalhara | C31: 782090547 | E31: 200128203490
A32: 31 | B32: Kodithuwakku Arachchige Chanaka Deshapriya | C32: 765538144 | E32: 200330112770
A33: 32 | B33: Isuru&Samitha | C33: 766874429 | D33: 712650654 | E33: 200002401011
A34: 33 | B34: Gamage Narthana Jananjaya Samaranayake | C34: 774451596 | E34: 199436504395
A35: 34 | B35: Samaramannage Pathum Shanaka Ranasinghe | C35: 717454424 | E35: 200019503520
A36: 35 | B36: Yasiru Banuka Abhaya Senarath | C36: 765926343 | E36: 200333112227
A37: 36 | B37: Ranhoti Asurappuli Gamage Yasiru Nimesh | C37: 705156467 | E37: 200027602477
A38: 37 | B38: Hadun Arachchige Ashen Kalpitha Liyanage | C38: 704962539 | E38: 200519404424
A39: 38 | B39: Marappuli Durage Dilshan Madhusanka Nipunajith | C39: 764504189 | E39: 990702047V
A40: 39 | B40: Hewa Magallagodage Kamal Sanjeewa | C40: 719647516 | E40: 199428601729
...
